Workbook

Sheet итог
A1: sku_type_sap | B1: brand | C1: LITRAG | D1: ФОРМАТ | E1: itog
A2: COLA Fresh Bar 0,45 CAN | B2: =VLOOKUP(Append1[[#This Row],[sku_type_sap]],Лист1!A:G,2,0) -> COLA BY FRESH BAR | C2: =VLOOKUP(Append1[[#This Row],[sku_type_sap]],Лист1!A:G,3,0) -> 0.45 | D2: =VLOOKUP(Append1[[#This Row],[sku_type_sap]],Лист1!A:G,4,0) -> CAN | E2: =VLOOKUP(Append1[[#This Row],[sku_type_sap]],Лист1!A:G,5,0) -> COLA BY FRESH BAR 0,45 CAN
A3: COLA Fresh Bar 0,48 PET | B3: =VLOOKUP(Append1[[#This Row],[sku_type_sap]],Лист1!A:G,2,0) -> COLA BY FRESH BAR | C3: =VLOOKUP(Append1[[#This Row],[sku_type_sap]],Лист1!A:G,3,0) -> 0.48 | D3: =VLOOKUP(Append1[[#This Row],[sku_type_sap]],Лист1!A:G,4,0) -> PET | E3: =VLOOKUP(Append1[[#This Row],[sku_type_sap]],Лист1!A:G,5,0) -> COLA BY FRESH BAR 0,48 PET
A4: COLA Fresh Bar 1,5 PET | B4: =VLOOKUP(Append1[[#This Row],[sku_type_sap]],Лист1!A:G,2,0) -> COLA BY FRESH BAR | C4: =VLOOKUP(Append1[[#This Row],[sku_type_sap]],Лист1!A:G,3,0) -> 1.5 | D4: =VLOOKUP(Append1[[#This Row],[sku_type_sap]],Лист1!A:G,4,0) -> PET | E4: =VLOOKUP(Append1[[#This Row],[sku_type_sap]],Лист1!A:G,5,0) -> COLA BY FRESH BAR 1,5 PET
A5: E-ON 0,25 CAN | B5: =VLOOKUP(Append1[[#This Row],[sku_type_sap]],Лист1!A:G,2,0) -> E-ON | C5: =VLOOKUP(Append1[[#This Row],[sku_type_sap]],Лист1!A:G,3,0) -> 0.25 | D5: =VLOOKUP(Append1[[#This Row],[sku_type_sap]],Лист1!A:G,4,0) -> CAN | E5: =VLOOKUP(Append1[[#This Row],[sku_type_sap]],Лист1!A:G,5,0) -> E-ON 0,25 CAN
A6: E-ON 0,45 CAN | B6: =VLOOKUP(Append1[[#This Row],[sku_type_sap]],Лист1!A:G,2,0) -> E-ON | C6: =VLOOKUP(Append1[[#This Row],[sku_type_sap]],Лист1!A:G,3,0) -> 0.45 | D6: =VLOOKUP(Append1[[#This Row],[sku_type_sap]],Лист1!A:G,4,0) -> CAN | E6: =VLOOKUP(Append1[[#This Row],[sku_type_sap]],Лист1!A:G,5,0) -> E-ON 0,45 CAN
A7: E-ON BCAA 0,45 CAN | B7: =VLOOKUP(Append1[[#This Row],[sku_type_sap]],Лист1!A:G,2,0) -> E-ON | C7: =VLOOKUP(Append1[[#This Row],[sku_type_sap]],Лист1!A:G,3,0) -> 0.45 | D7: =VLOOKUP(Append1[[#This Row],[sku_type_sap]],Лист1!A:G,4,0) -> CAN | E7: =VLOOKUP(Append1[[#This Row],[sku_type_sap]],Лист1!A:G,5,0) -> E-ON 0,45 CAN
A8: Fresh Bar 0,45 CAN | B8: =VLOOKUP(Append1[[#This Row],[sku_type_sap]],Лист1!A:G,2,0) -> FRESH BAR | C8: =VLOOKUP(Append1[[#This Row],[sku_type_sap]],Лист1!A:G,3,0) -> 0.45 | D8: =VLOOKUP(Append1[[#This Row],[sku_type_sap]],Лист1!A:G,4,0) -> CAN | E8: =VLOOKUP(Append1[[#This Row],[sku_type_sap]],Лист1!A:G,5,0) -> FRESH BAR 0,45 CAN
A9: Fresh Bar 0,48 PET | B9: =VLOOKUP(Append1[[#This Row],[sku_type_sap]],Лист1!A:G,2,0) -> FRESH BAR | C9: =VLOOKUP(Append1[[#This Row],[sku_type_sap]],Лист1!A:G,3,0) -> 0.48 | D9: =VLOOKUP(Append1[[#This Row],[sku_type_sap]],Лист1!A:G,4,0) -> PET | E9: =VLOOKUP(Append1[[#This Row],[sku_type_sap]],Лист1!A:G,5,0) -> FRESH BAR 0,48 PET
A10: Fresh Bar 1,5 PET | B10: =VLOOKUP(Append1[[#This Row],[sku_type_sap]],Лист1!A:G,2,0) -> FRESH BAR | C10: =VLOOKUP(Append1[[#This Row],[sku_type_sap]],Лист1!A:G,3,0) -> 1.5 | D10: =VLOOKUP(Append1[[#This Row],[sku_type_sap]],Лист1!A:G,4,0) -> PET | E10: =VLOOKUP(Append1[[#This Row],[sku_type_sap]],Лист1!A:G,5,0) -> FRESH BAR 1,5 PET
A11: Tornado 0,45 CAN | B11: =VLOOKUP(Append1[[#This Row],[sku_type_sap]],Лист1!A:G,2,0) -> TORNADO | C11: =VLOOKUP(Append1[[#This Row],[sku_type_sap]],Лист1!A:G,3,0) -> 0.45 | D11: =VLOOKUP(Append1[[#This Row],[sku_type_sap]],Лист1!A:G,4,0) -> CAN | E11: =VLOOKUP(Append1[[#This Row],[sku_type_sap]],Лист1!A:G,5,0) -> TORNADO 0,45 CAN
A12: Tornado 0,473 PET | B12: =VLOOKUP(Append1[[#This Row],[sku_type_sap]],Лист1!A:G,2,0) -> TORNADO | C12: =VLOOKUP(Append1[[#This Row],[sku_type_sap]],Лист1!A:G,3,0) -> 0.473 | D12: =VLOOKUP(Append1[[#This Row],[sku_type_sap]],Лист1!A:G,4,0) -> PET | E12: =VLOOKUP(Append1[[#This Row],[sku_type_sap]],Лист1!A:G,5,0) -> TORNADO 0,473 PET
A13: Tornado 1,0 PET | B13: =VLOOKUP(Append1[[#This Row],[sku_type_sap]],Лист1!A:G,2,0) -> TORNADO | C13: =VLOOKUP(Append1[[#This Row],[sku_type_sap]],Лист1!A:G,3,0) -> 1 | D13: =VLOOKUP(Append1[[#This Row],[sku_type_sap]],Лист1!A:G,4,0) -> PET | E13: =VLOOKUP(Append1[[#This Row],[sku_type_sap]],Лист1!A:G,5,0) -> TORNADO 1 PET
... A37: Tornado 0,473 MAX PET | B37: =VLOOKUP(Append1[[#This Row],[sku_type_sap]],Лист1!A:G,2,0) -> TORNADO MAX | C37: =VLOOKUP(Append1[[#This Row],[sku_type_sap]],Лист1!A:G,3,0) -> 0.473 | D37: =VLOOKUP(Append1[[#This Row],[sku_type_sap]],Лист1!A:G,4,0) -> PET | E37: =VLOOKUP(Append1[[#This Row],[sku_type_sap]],Лист1!A:G,5,0) -> TORNADO MAX 0,473 PET
A38: Tornado 0,33 CAN Только для КИБа | B38: TORNADO MAX | C38: =VLOOKUP(Append1[[#This Row],[sku_type_sap]],Лист1!A:G,3,0) -> 0.33 | D38: =VLOOKUP(Append1[[#This Row],[sku_type_sap]],Лист1!A:G,4,0) -> CAN | E38: =VLOOKUP(Append1[[#This Row],[sku_type_sap]],Лист1!A:G,5,0) -> TORNADO MAX 0,33 CAN
A39: E-On 0,45 CAN | B39: =VLOOKUP(Append1[[#This Row],[sku_type_sap]],Лист1!A:G,2,0) -> E-ON | C39: =VLOOKUP(Append1[[#This Row],[sku_type_sap]],Лист1!A:G,3,0) -> 0.45 | D39: =VLOOKUP(Append1[[#This Row],[sku_type_sap]],Лист1!A:G,4,0) -> CAN | E39: =VLOOKUP(Append1[[#This Row],[sku_type_sap]],Лист1!A:G,5,0) -> E-ON 0,45 CAN
A40: FB Cola 1,5 | B40: =VLOOKUP(Append1[[#This Row],[sku_type_sap]],Лист1!A:G,2,0) -> COLA BY FRESH BAR | C40: =VLOOKUP(Append1[[#This Row],[sku_type_sap]],Лист1!A:G,3,0) -> 1.5 | D40: =VLOOKUP(Append1[[#This Row],[sku_type_sap]],Лист1!A:G,4,0) -> PET | E40: =VLOOKUP(Append1[[#This Row],[sku_type_sap]],Лист1!A:G,5,0) -> COLA BY FRESH BAR 1,5 PET
A41: FB Cola 0,45 Can | B41: =VLOOKUP(Append1[[#This Row],[sku_type_sap]],Лист1!A:G,2,0) -> COLA BY FRESH BAR | C41: =VLOOKUP(Append1[[#This Row],[sku_type_sap]],Лист1!A:G,3,0) -> 0.45 | D41: =VLOOKUP(Append1[[#This Row],[sku_type_sap]],Лист1!A:G,4,0) -> CAN | E41: =VLOOKUP(Append1[[#This Row],[sku_type_sap]],Лист1!A:G,5,0) -> COLA BY FRESH BAR 0,45 CAN
A42: Tornado 0,45 CAN max | B42: =VLOOKUP(Append1[[#This Row],[sku_type_sap]],Лист1!A:G,2,0) -> TORNADO MAX | C42: =VLOOKUP(Append1[[#This Row],[sku_type_sap]],Лист1!A:G,3,0) -> 0.45 | D42: =VLOOKUP(Append1[[#This Row],[sku_type_sap]],Лист1!A:G,4,0) -> CAN | E42: =VLOOKUP(Append1[[#This Row],[sku_type_sap]],Лист1!A:G,5,0) -> TORNADO MAX 0,45 CAN
A43: Tornado 0,473 PET max | B43: =VLOOKUP(Append1[[#This Row],[sku_type_sap]],Лист1!A:G,2,0) -> TORNADO MAX | C43: =VLOOKUP(Append1[[#This Row],[sku_type_sap]],Лист1!A:G,3,0) -> 0.473 | D43: =VLOOKUP(Append1[[#This Row],[sku_type_sap]],Лист1!A:G,4,0) -> PET | E43: =VLOOKUP(Append1[[#This Row],[sku_type_sap]],Лист1!A:G,5,0) -> TORNADO MAX 0,473 PET
A44: E-ON 0,45 CAN | B44: =VLOOKUP(Append1[[#This Row],[sku_type_sap]],Лист1!A:G,2,0) -> E-ON | C44: =VLOOKUP(Append1[[#This Row],[sku_type_sap]],Лист1!A:G,3,0) -> 0.45 | D44: =VLOOKUP(Append1[[#This Row],[sku_type_sap]],Лист1!A:G,4,0) -> CAN | E44: =VLOOKUP(Append1[[#This Row],[sku_type_sap]],Лист1!A:G,5,0) -> E-ON 0,45 CAN
A45: E-ON 0,5 PET | B45: =VLOOKUP(Append1[[#This Row],[sku_type_sap]],Лист1!A:G,2,0) -> E-ON | C45: =VLOOKUP(Append1[[#This Row],[sku_type_sap]],Лист1!A:G,3,0) -> 0.5 | D45: =VLOOKUP(Append1[[#This Row],[sku_type_sap]],Лист1!A:G,4,0) -> PET | E45: =VLOOKUP(Append1[[#This Row],[sku_type_sap]],Лист1!A:G,5,0) -> E-ON 0,5 PET
A46: COLA BY FRESH BAR 0,48 PET | B46: =VLOOKUP(Append1[[#This Row],[sku_type_sap]],Лист1!A:G,2,0) -> COLA BY FRESH BAR | C46: =VLOOKUP(Append1[[#This Row],[sku_type_sap]],Лист1!A:G,3,0) -> 0.48 | D46: =VLOOKUP(Append1[[#This Row],[sku_type_sap]],Лист1!A:G,4,0) -> PET | E46: =VLOOKUP(Append1[[#This Row],[sku_type_sap]],Лист1!A:G,5,0) -> COLA BY FRESH BAR 0,48 PET
A47: COLA BY FRESH BAR 1,5 PET | B47: =VLOOKUP(Append1[[#This Row],[sku_type_sap]],Лист1!A:G,2,0) -> COLA BY FRESH BAR | C47: =VLOOKUP(Append1[[#This Row],[sku_type_sap]],Лист1!A:G,3,0) -> 1.5 | D47: =VLOOKUP(Append1[[#This Row],[sku_type_sap]],Лист1!A:G,4,0) -> PET | E47: =VLOOKUP(Append1[[#This Row],[sku_type_sap]],Лист1!A:G,5,0) -> COLA BY FRESH BAR 1,5 PET
A48: COLA BY FRESH BAR 0,45 CAN | B48: =VLOOKUP(Append1[[#This Row],[sku_type_sap]],Лист1!A:G,2,0) -> COLA BY FRESH BAR | C48: =VLOOKUP(Append1[[#This Row],[sku_type_sap]],Лист1!A:G,3,0) -> 0.45 | D48: =VLOOKUP(Append1[[#This Row],[sku_type_sap]],Лист1!A:G,4,0) -> CAN | E48: =VLOOKUP(Append1[[#This Row],[sku_type_sap]],Лист1!A:G,5,0) -> COLA BY FRESH BAR 0,45 CAN
A49: FRESH BAR 0,45 CAN | B49: =VLOOKUP(Append1[[#This Row],[sku_type_sap]],Лист1!A:G,2,0) -> FRESH BAR | C49: =VLOOKUP(Append1[[#This Row],[sku_type_sap]],Лист1!A:G,3,0) -> 0.45 | D49: =VLOOKUP(Append1[[#This Row],[sku_type_sap]],Лист1!A:G,4,0) -> CAN | E49: =VLOOKUP(Append1[[#This Row],[sku_type_sap]],Лист1!A:G,5,0) -> FRESH BAR 0,45 CAN
A50: FRESH BAR 0,45 CAN | B50: =VLOOKUP(Append1[[#This Row],[sku_type_sap]],Лист1!A:G,2,0) -> FRESH BAR | C50: =VLOOKUP(Append1[[#This Row],[sku_type_sap]],Лист1!A:G,3,0) -> 0.45 | D50: =VLOOKUP(Append1[[#This Row],[sku_type_sap]],Лист1!A:G,4,0) -> CAN | E50: =VLOOKUP(Append1[[#This Row],[sku_type_sap]],Лист1!A:G,5,0) -> FRESH BAR 0,45 CAN
... A86: TORNADO MAX 0,473 PET | B86: =VLOOKUP(Append1[[#This Row],[sku_type_sap]],Лист1!A:G,2,0) -> TORNADO MAX | C86: =VLOOKUP(Append1[[#This Row],[sku_type_sap]],Лист1!A:G,3,0) -> 0.473 | D86: =VLOOKUP(Append1[[#This Row],[sku_type_sap]],Лист1!A:G,4,0) -> PET | E86: =VLOOKUP(Append1[[#This Row],[sku_type_sap]],Лист1!A:G,5,0) -> TORNADO MAX 0,473 PET
A87: Tornado 0,33 CAN | B87: TORNADO MAX | C87: 0.33 | D87: CAN | E87: TORNADO MAX 0,33 CAN
A88: Tornado 0,45 CAN max | B88: =VLOOKUP(Append1[[#This Row],[sku_type_sap]],Лист1!A:G,2,0) -> TORNADO MAX | C88: =VLOOKUP(Append1[[#This Row],[sku_type_sap]],Лист1!A:G,3,0) -> 0.45 | D88: =VLOOKUP(Append1[[#This Row],[sku_type_sap]],Лист1!A:G,4,0) -> CAN | E88: =VLOOKUP(Append1[[#This Row],[sku_type_sap]],Лист1!A:G,5,0) -> TORNADO MAX 0,45 CAN
A89: Fresh Bar 0,45 CAN | B89: =VLOOKUP(Append1[[#This Row],[sku_type_sap]],Лист1!A:G,2,0) -> FRESH BAR | C89: =VLOOKUP(Append1[[#This Row],[sku_type_sap]],Лист1!A:G,3,0) -> 0.45 | D89: =VLOOKUP(Append1[[#This Row],[sku_type_sap]],Лист1!A:G,4,0) -> CAN | E89: =VLOOKUP(Append1[[#This Row],[sku_type_sap]],Лист1!A:G,5,0) -> FRESH BAR 0,45 CAN
A90: Fresh Bar 1,5л | B90: =VLOOKUP(Append1[[#This Row],[sku_type_sap]],Лист1!A:G,2,0) -> FRESH BAR | C90: =VLOOKUP(Append1[[#This Row],[sku_type_sap]],Лист1!A:G,3,0) -> 1.5 | D90: =VLOOKUP(Append1[[#This Row],[sku_type_sap]],Лист1!A:G,4,0) -> PET | E90: =VLOOKUP(Append1[[#This Row],[sku_type_sap]],Лист1!A:G,5,0) -> FRESH BAR 1,5 PET
A91: Tornado 1,0 PET | B91: =VLOOKUP(Append1[[#This Row],[sku_type_sap]],Лист1!A:G,2,0) -> TORNADO | C91: =VLOOKUP(Append1[[#This Row],[sku_type_sap]],Лист1!A:G,3,0) -> 1 | D91: =VLOOKUP(Append1[[#This Row],[sku_type_sap]],Лист1!A:G,4,0) -> PET | E91: =VLOOKUP(Append1[[#This Row],[sku_type_sap]],Лист1!A:G,5,0) -> TORNADO 1 PET
A92: Cola by FB 0,48 PET | B92: =VLOOKUP(Append1[[#This Row],[sku_type_sap]],Лист1!A:G,2,0) -> COLA BY FRESH BAR | C92: =VLOOKUP(Append1[[#This Row],[sku_type_sap]],Лист1!A:G,3,0) -> 0.48 | D92: =VLOOKUP(Append1[[#This Row],[sku_type_sap]],Лист1!A:G,4,0) -> PET | E92: =VLOOKUP(Append1[[#This Row],[sku_type_sap]],Лист1!A:G,5,0) -> COLA BY FRESH BAR 0,48 PET
A93: E-ON 0,45 CAN | B93: =VLOOKUP(Append1[[#This Row],[sku_type_sap]],Лист1!A:G,2,0) -> E-ON | C93: =VLOOKUP(Append1[[#This Row],[sku_type_sap]],Лист1!A:G,3,0) -> 0.45 | D93: =VLOOKUP(Append1[[#This Row],[sku_type_sap]],Лист1!A:G,4,0) -> CAN | E93: =VLOOKUP(Append1[[#This Row],[sku_type_sap]],Лист1!A:G,5,0) -> E-ON 0,45 CAN
A94: Fresh Bar 1,5 PET | B94: =VLOOKUP(Append1[[#This Row],[sku_type_sap]],Лист1!A:G,2,0) -> FRESH BAR | C94: =VLOOKUP(Append1[[#This Row],[sku_type_sap]],Лист1!A:G,3,0) -> 1.5 | D94: =VLOOKUP(Append1[[#This Row],[sku_type_sap]],Лист1!A:G,4,0) -> PET | E94: =VLOOKUP(Append1[[#This Row],[sku_type_sap]],Лист1!A:G,5,0) -> FRESH BAR 1,5 PET
A95: Tornado 0,45 CAN | B95: =VLOOKUP(Append1[[#This Row],[sku_type_sap]],Лист1!A:G,2,0) -> TORNADO | C95: =VLOOKUP(Append1[[#This Row],[sku_type_sap]],Лист1!A:G,3,0) -> 0.45 | D95: =VLOOKUP(Append1[[#This Row],[sku_type_sap]],Лист1!A:G,4,0) -> CAN | E95: =VLOOKUP(Append1[[#This Row],[sku_type_sap]],Лист1!A:G,5,0) -> TORNADO 0,45 CAN
A96: Cola by 1,5 PET | B96: =VLOOKUP(Append1[[#This Row],[sku_type_sap]],Лист1!A:G,2,0) -> COLA BY FRESH BAR | C96: =VLOOKUP(Append1[[#This Row],[sku_type_sap]],Лист1!A:G,3,0) -> 1.5 | D96: =VLOOKUP(Append1[[#This Row],[sku_type_sap]],Лист1!A:G,4,0) -> PET | E96: =VLOOKUP(Append1[[#This Row],[sku_type_sap]],Лист1!A:G,5,0) -> COLA BY FRESH BAR 1,5 PET
A97: Cola by FB 0,45 CAN | B97: =VLOOKUP(Append1[[#This Row],[sku_type_sap]],Лист1!A:G,2,0) -> COLA BY FRESH BAR | C97: =VLOOKUP(Append1[[#This Row],[sku_type_sap]],Лист1!A:G,3,0) -> 0.45 | D97: =VLOOKUP(Append1[[#This Row],[sku_type_sap]],Лист1!A:G,4,0) -> CAN | E97: =VLOOKUP(Append1[[#This Row],[sku_type_sap]],Лист1!A:G,5,0) -> COLA BY FRESH BAR 0,45 CAN
A98: Cola by FB 1,5 PET | B98: =VLOOKUP(Append1[[#This Row],[sku_type_sap]],Лист1!A:G,2,0) -> COLA BY FRESH BAR | C98: =VLOOKUP(Append1[[#This Row],[sku_type_sap]],Лист1!A:G,3,0) -> 1.5 | D98: =VLOOKUP(Append1[[#This Row],[sku_type_sap]],Лист1!A:G,4,0) -> PET | E98: =VLOOKUP(Append1[[#This Row],[sku_type_sap]],Лист1!A:G,5,0) -> COLA BY FRESH BAR 1,5 PET
...

Sheet Лист1
A1: brand | B1: brand | C1: LITRAG | D1: ФОРМАТ | E1: itog
A2: COLA Fresh Bar 0,45 CAN | B2: COLA BY FRESH BAR | C2: 0.45 | D2: CAN | E2: =CONCATENATE(B2," ",C2," ",D2) -> COLA BY FRESH BAR 0,45 CAN
A3: COLA Fresh Bar 0,48 PET | B3: COLA BY FRESH BAR | C3: 0.48 | D3: PET | E3: =CONCATENATE(B3," ",C3," ",D3) -> COLA BY FRESH BAR 0,48 PET | M3: Tornado 0,45 CAN max
A4: COLA Fresh Bar 1,5 PET | B4: COLA BY FRESH BAR | C4: 1.5 | D4: PET | E4: =CONCATENATE(B4," ",C4," ",D4) -> COLA BY FRESH BAR 1,5 PET | M4: Fresh Bar 0,45 CAN
A5: E-ON 0,25 CAN | B5: E-ON | C5: 0.25 | D5: CAN | E5: =CONCATENATE(B5," ",C5," ",D5) -> E-ON 0,25 CAN | M5: Fresh Bar 0,48 PET
A6: E-ON 0,45 CAN | B6: E-ON | C6: 0.45 | D6: CAN | E6: =CONCATENATE(B6," ",C6," ",D6) -> E-ON 0,45 CAN | M6: Fresh Bar 1,5л
A7: E-ON BCAA 0,45 CAN | B7: E-ON | C7: 0.45 | D7: CAN | E7: =CONCATENATE(B7," ",C7," ",D7) -> E-ON 0,45 CAN | M7: Tornado 1,0 PET
A8: Fresh Bar 0,45 CAN | B8: FRESH BAR | C8: 0.45 | D8: CAN | E8: =CONCATENATE(B8," ",C8," ",D8) -> FRESH BAR 0,45 CAN | M8: Cola by FB 0,48 PET
A9: Fresh Bar 0,48 PET | B9: FRESH BAR | C9: 0.48 | D9: PET | E9: =CONCATENATE(B9," ",C9," ",D9) -> FRESH BAR 0,48 PET | M9: E-ON 0,45 CAN
A10: Fresh Bar 1,5 PET | B10: FRESH BAR | C10: 1.5 | D10: PET | E10: =CONCATENATE(B10," ",C10," ",D10) -> FRESH BAR 1,5 PET | M10: Fresh Bar 1,5 PET
A11: Tornado 0,45 CAN | B11: TORNADO | C11: 0.45 | D11: CAN | E11: =CONCATENATE(B11," ",C11," ",D11) -> TORNADO 0,45 CAN | M11: Tornado 0,45 CAN
A12: Tornado 0,473 PET | B12: TORNADO | C12: 0.473 | D12: PET | E12: =CONCATENATE(B12," ",C12," ",D12) -> TORNADO 0,473 PET | M12: Cola by 1,5 PET
A13: Tornado 1,0 PET | B13: TORNADO | C13: 1 | D13: PET | E13: =CONCATENATE(B13," ",C13," ",D13) -> TORNADO 1 PET | M13: Cola by FB 0,45 CAN
A14: ИЛ 0,45 CAN | B14: ИЛ | C14: 0.45 | D14: CAN | E14: =CONCATENATE(B14," ",C14," ",D14) -> ИЛ 0,45 CAN | M14: Cola by FB 1,5 PET
... A16: ИЛ 1,42 PET | B16: ИЛ | C16: 1.42 | D16: PET | E16: =CONCATENATE(B16," ",C16," ",D16) -> ИЛ 1,42 PET | M16: Tornado 0,473 PET
A17: Tornado MAX 0,45 CAN | B17: TORNADO MAX | C17: 0.45 | D17: CAN | E17: =CONCATENATE(B17," ",C17," ",D17) -> TORNADO MAX 0,45 CAN
A18: Tornado MAX 0,473 PET | B18: TORNADO MAX | C18: 0.473 | D18: PET | E18: =CONCATENATE(B18," ",C18," ",D18) -> TORNADO MAX 0,473 PET
A19: Tornado сахар 0,45 CAN | B19: TORNADO MAX | C19: 0.45 | D19: CAN | E19: =CONCATENATE(B19," ",C19," ",D19) -> TORNADO MAX 0,45 CAN
A20: Tornado сахар 0,473 PET | B20: TORNADO MAX | C20: 0.473 | D20: PET | E20: =CONCATENATE(B20," ",C20," ",D20) -> TORNADO MAX 0,473 PET
A21: Fresh Bar 1,0 PET | B21: FRESH BAR | C21: 1 | D21: PET | E21: =CONCATENATE(B21," ",C21," ",D21) -> FRESH BAR 1 PET
A22: COLA Fresh Bar 1,0 PET | B22: COLA BY FRESH BAR | C22: 1 | D22: PET | E22: =CONCATENATE(B22," ",C22," ",D22) -> COLA BY FRESH BAR 1 PET
A23: FRESH BAR 1,0 PET | B23: FRESH BAR | C23: 1 | D23: PET | E23: =CONCATENATE(B23," ",C23," ",D23) -> FRESH BAR 1 PET
A24: FRESH BAR COLA 0,45 CAN | B24: COLA BY FRESH BAR | C24: 0.45 | D24: CAN | E24: =CONCATENATE(B24," ",C24," ",D24) -> COLA BY FRESH BAR 0,45 CAN
A25: FRESH BAR COLA 0,48 PET | B25: COLA BY FRESH BAR | C25: 0.48 | D25: PET | E25: =CONCATENATE(B25," ",C25," ",D25) -> COLA BY FRESH BAR 0,48 PET
A26: FRESH BAR COLA 1,5 PET | B26: COLA BY FRESH BAR | C26: 1.5 | D26: PET | E26: =CONCATENATE(B26," ",C26," ",D26) -> COLA BY FRESH BAR 1,5 PET
A27: Tornado 0,45 CAN MAX | B27: TORNADO MAX | C27: 0.45 | D27: CAN | E27: =CONCATENATE(B27," ",C27," ",D27) -> TORNADO MAX 0,45 CAN
A28: Tornado 0,473 PET MAX | B28: TORNADO MAX | C28: 0.473 | D28: PET | E28: =CONCATENATE(B28," ",C28," ",D28) -> TORNADO MAX 0,473 PET
... A43: Tornado 0,473 PET max | B43: TORNADO MAX | C43: 0.473 | D43: PET | E43: =CONCATENATE(B43," ",C43," ",D43) -> TORNADO MAX 0,473 PET
A44: E-ON 0,45 CAN | B44: E-ON | C44: 0.45 | D44: CAN | E44: =VLOOKUP(A44,Append1[sku_type_sap],1,0) -> E-ON 0,45 CAN
A45: E-ON 0,5 PET | B45: E-ON | C45: 0.5 | D45: PET | E45: =VLOOKUP(A45,Append1[sku_type_sap],1,0) -> E-ON 0,5 PET
A46: COLA BY FRESH BAR 0,48 PET | B46: COLA BY FRESH BAR | C46: 0.48 | D46: PET | E46: =VLOOKUP(A46,Append1[sku_type_sap],1,0) -> COLA BY FRESH BAR 0,48 PET
A47: COLA BY FRESH BAR 1,5 PET | B47: COLA BY FRESH BAR | C47: 1.5 | D47: PET | E47: =VLOOKUP(A47,Append1[sku_type_sap],1,0) -> COLA BY FRESH BAR 1,5 PET
A48: COLA BY FRESH BAR 0,45 CAN | B48: COLA BY FRESH BAR | C48: 0.45 | D48: CAN | E48: =VLOOKUP(A48,Append1[sku_type_sap],1,0) -> COLA BY FRESH BAR 0,45 CAN
A49: FRESH BAR 0,45 CAN | B49: FRESH BAR | C49: 0.45 | D49: CAN | E49: =VLOOKUP(A49,Append1[sku_type_sap],1,0) -> Fresh Bar 0,45 CAN
A50: FRESH BAR 0,45 CAN | B50: FRESH BAR | C50: 0.45 | D50: CAN | E50: =VLOOKUP(A50,Append1[sku_type_sap],1,0) -> Fresh Bar 0,45 CAN
A51: COLA BY FRESH BAR 0,45 CAN | B51: COLA BY FRESH BAR | C51: 0.45 | D51: CAN | E51: =VLOOKUP(A51,Append1[sku_type_sap],1,0) -> COLA BY FRESH BAR 0,45 CAN
A52: FRESH BAR 0,48 PET | B52: FRESH BAR | C52: 0.48 | D52: PET | E52: =VLOOKUP(A52,Append1[sku_type_sap],1,0) -> Fresh Bar 0,48 PET
A53: FRESH BAR 0,48 PET | B53: FRESH BAR | C53: 0.48 | D53: PET | E53: =VLOOKUP(A53,Append1[sku_type_sap],1,0) -> Fresh Bar 0,48 PET
A54: COLA BY FRESH BAR 0,48 PET | B54: COLA BY FRESH BAR | C54: 0.48 | D54: PET | E54: =VLOOKUP(A54,Append1[sku_type_sap],1,0) -> COLA BY FRESH BAR 0,48 PET
A55: FRESH BAR 0,48 PET | B55: FRESH BAR | C55: 0.48 | D55: PET | E55: =VLOOKUP(A55,Append1[sku_type_sap],1,0) -> Fresh Bar 0,48 PET
...

Sheet Лист2
D1: Продукт | E1: БРЕНД | F1: ЛИТРАЖ | G1: ФОРМАТ
D2: E-ON 0,45 CAN | E2: E-ON | F2: 0.45 | G2: CAN | H2: =CONCATENATE(E2,I2,F2,I2,G2) -> E-ON 0,45 CAN | J2: =VLOOKUP(H2,итог!E:E,1,0) -> E-ON 0,45 CAN
D3: E-ON 0,5 | E3: E-ON | F3: 0.5 | G3: PET | H3: =CONCATENATE(E3,I3,F3,I3,G3) -> E-ON 0,5 PET | J3: =VLOOKUP(H3,итог!E:E,1,0) -> E-ON 0,5 PET
D4: Freh Bar 0,48 Cola | E4: COLA BY FRESH BAR | F4: 0.48 | G4: PET | H4: =CONCATENATE(E4,I4,F4,I4,G4) -> COLA BY FRESH BAR 0,48 PET | J4: =VLOOKUP(H4,итог!E:E,1,0) -> COLA BY FRESH BAR 0,48 PET
D5: Freh Bar 1,5 Cola | E5: COLA BY FRESH BAR | F5: 1.5 | G5: PET | H5: =CONCATENATE(E5,I5,F5,I5,G5) -> COLA BY FRESH BAR 1,5 PET | J5: =VLOOKUP(H5,итог!E:E,1,0) -> COLA BY FRESH BAR 1,5 PET
D6: Fresh Bar 0,45 COLA жб | E6: COLA BY FRESH BAR | F6: 0.45 | G6: CAN | H6: =CONCATENATE(E6,I6,F6,I6,G6) -> COLA BY FRESH BAR 0,45 CAN | J6: =VLOOKUP(H6,итог!E:E,1,0) -> COLA BY FRESH BAR 0,45 CAN
D7: Fresh Bar 0,45 жб | E7: FRESH BAR | F7: 0.45 | G7: CAN | H7: =CONCATENATE(E7,I7,F7,I7,G7) -> FRESH BAR 0,45 CAN | J7: =VLOOKUP(H7,итог!E:E,1,0) -> FRESH BAR 0,45 CAN
D8: Fresh Bar 0,45 жб | E8: FRESH BAR | F8: 0.45 | G8: CAN | H8: =CONCATENATE(E8,I8,F8,I8,G8) -> FRESH BAR 0,45 CAN | J8: =VLOOKUP(H8,итог!E:E,1,0) -> FRESH BAR 0,45 CAN
D9: Fresh Bar 0,45 жб COLA | E9: COLA BY FRESH BAR | F9: 0.45 | G9: CAN | H9: =CONCATENATE(E9,I9,F9,I9,G9) -> COLA BY FRESH BAR 0,45 CAN | J9: =VLOOKUP(H9,итог!E:E,1,0) -> COLA BY FRESH BAR 0,45 CAN
D10: Fresh Bar 0,48 | E10: FRESH BAR | F10: 0.48 | G10: PET | H10: =CONCATENATE(E10,I10,F10,I10,G10) -> FRESH BAR 0,48 PET | J10: =VLOOKUP(H10,итог!E:E,1,0) -> FRESH BAR 0,48 PET
D11: Fresh Bar 0,48 | E11: FRESH BAR | F11: 0.48 | G11: PET | H11: =CONCATENATE(E11,I11,F11,I11,G11) -> FRESH BAR 0,48 PET | J11: =VLOOKUP(H11,итог!E:E,1,0) -> FRESH BAR 0,48 PET
D12: Fresh Bar 0,48 COLA | E12: COLA BY FRESH BAR | F12: 0.48 | G12: PET | H12: =CONCATENATE(E12,I12,F12,I12,G12) -> COLA BY FRESH BAR 0,48 PET | J12: =VLOOKUP(H12,итог!E:E,1,0) -> COLA BY FRESH BAR 0,48 PET
D13: Fresh Bar 0,48 жб | E13: FRESH BAR | F13: 0.48 | G13: PET | H13: =CONCATENATE(E13,I13,F13,I13,G13) -> FRESH BAR 0,48 PET | J13: =VLOOKUP(H13,итог!E:E,1,0) -> FRESH BAR 0,48 PET
... D53: Tornado 0,473 PET max | E53: TORNADO MAX | F53: 0.473 | G53: PET | H53: =CONCATENATE(E53,I53,F53,I53,G53) -> TORNADO MAX 0,473 PET | J53: =VLOOKUP(H53,итог!E:E,1,0) -> TORNADO MAX 0,473 PET

Sheet ecp data
A1: sku_type_sap
A2: COLA Fresh Bar 0,45 CAN
A3: COLA Fresh Bar 0,48 PET
A4: COLA Fresh Bar 1,5 PET
A5: E-ON 0,25 CAN
A6: E-ON 0,45 CAN
A7: E-ON BCAA 0,45 CAN
A8: Fresh Bar 0,45 CAN
A9: Fresh Bar 0,48 PET
A10: Fresh Bar 1,5 PET
A11: Tornado 0,45 CAN
A12: Tornado 0,473 PET
... A22: COLA Fresh Bar 1,0 PET

Sheet себес
A1: sku_type_sap
A2: E-ON 0,45 CAN
A3: Fresh Bar 0,48 PET
A4: Tornado 0,45 CAN
A5: Tornado 0,473 PET
A6: Tornado 1,0 PET
A7: ИЛ 0,45 CAN
A8: E-ON BCAA 0,45 CAN
A9: Fresh Bar 1,5 PET
A10: ИЛ 1,42 PET
A11: Fresh Bar 0,45 CAN
A12: COLA Fresh Bar 0,48 PET
... A21: ИЛ 0,48 PET

Sheet sales
A1: sku_type_sap
A2: Tornado 0,473 PET
A3: Tornado 0,45 CAN
A4: Торнадо ж/б 0,25
A5: Tornado 1,0 PET
A6: E-ON 0,25 CAN
A7: E-ON 0,45 CAN
A8: Fresh Bar 0,48 PET
A9: ИЛ 0,48 PET
A10: Fresh Bar 1,5 PET
A11: Fresh Bar 0,45 CAN
A12: ИЛ 1,42 PET
... A17: Fresh Bar 1л

Sheet цм
A1: sku_type_sap
A2: E-ON 0,45 CAN
A3: Fresh Bar 0,45 CAN
A4: Fresh Bar 0,48 PET
A5: Fresh Bar 1,5 PET
A6: COLA Fresh Bar 0,48 PET
A7: FB Cola 0,45 CAN
A8: COLA Fresh Bar 1,5 PET
A9: Tornado 0,473 PET
A10: Tornado 1,0 PET
A11: Tornado 0,45 CAN
A12: ИЛ 0,48 PET
... A20: Tornado 0,33 CAN Только для КИБа

Sheet в цене
A1: sku_type_sap
A2: Tornado 0,45 CAN
A3: Fresh Bar 0,48 PET
A4: E-On 0,45 CAN
A5: Tornado 1,0 PET
A6: ИЛ 0,48 PET
A7: Tornado 0,473 PET
A8: FB Cola 0,48 PET
A9: Fresh Bar 0,45 CAN
A10: FB Cola 1,5
A11: Fresh Bar 1,5 PET
A12: FB Cola 0,45 CAN
... A20: Fresh Bar 1,0 PET

Sheet вне цены
A1: sku_type_sap
A2: E-On 0,45 CAN
A3: Tornado 0,45 CAN
A4: Tornado 1,0 PET
A5: ИЛ 0,48 PET
A6: ИЛ 1,42 PET
A7: Tornado 0,473 PET
A8: FB Cola 0,45 CAN
A9: Fresh Bar 0,45 CAN
A10: Fresh Bar 0,48 PET
A11: FB Cola 0,48 PET
A12: Fresh Bar 1,5 PET
... A18: Tornado 0,473 PET max
